<?xml version="1.0" encoding="utf-8"?>
<!-- =================================================================================== -->
<!-- |    This document was autogenerated by xacro from demo/urdf/schunk/lwa4d_robot.urdf.xacro | -->
<!-- |    EDITING THIS FILE BY HAND IS NOT RECOMMENDED                                 | -->
<!-- =================================================================================== -->
<robot name="lwa4d" xmlns:xacro="http://www.ros.org/wiki/xacro">
  <!-- joint between base_link and lwa4p_extended_connector_link -->
  <joint name="robot_podest_joint" type="fixed">
    <link name="world"/>
    <parent link="world"/>
    <child link="robot_podest_link"/>
  </joint>
  <link name="robot_podest_link">
    <inertial>
      <mass value="0.01"/>
      <origin xyz="0 0 0"/>
      <inertia ixx="0.001" ixy="0.0" ixz="0.0" iyy="0.001" iyz="0.0" izz="0.001"/>
    </inertial>
    <visual>
      <geometry>
        <mesh filename="package://schunk_description/meshes/lwa4d/arm_podest_link.stl"/>
      </geometry>
      <material name="Schunk/LightGrey"/>
    </visual>
    <collision>
      <geometry>
        <mesh filename="package://schunk_description/meshes/lwa4d/arm_podest_link.stl"/>
      </geometry>
    </collision>
  </link>
  <joint name="robot_base_joint" type="fixed">
    <origin rpy="0 0 0" xyz="0 0 0.140"/>
    <parent link="robot_podest_link"/>
    <child link="robot_base_link"/>
  </joint>
  <link name="robot_base_link">
    <inertial>
      <mass value="0.01"/>
      <origin xyz="0 0 0"/>
      <inertia ixx="0.001" ixy="0.0" ixz="0.0" iyy="0.001" iyz="0.0" izz="0.001"/>
    </inertial>
  </link>
  <!-- joint between arm_base_link and arm_1_link -->
  <joint name="robot_1_joint" type="revolute">
    <origin rpy="0 0 0" xyz="0 0 0"/>
    <parent link="robot_base_link"/>
    <child link="robot_1_link"/>
    <axis xyz="0 0 -1"/>
    <limit effort="216" lower="-3.12159" upper="3.12159" velocity="0.43633"/>
  </joint>
  <link name="robot_1_link">
    <inertial>
      <mass value="0.01"/>
      <origin xyz="0 0 0"/>
      <inertia ixx="0.001" ixy="0.0" ixz="0.0" iyy="0.001" iyz="0.0" izz="0.001"/>
    </inertial>
    <!--
      <xacro:cylinder_inertial radius="0.06" length="0.150" mass="3.6">
          <origin xyz="0 0 0.02" rpy="0 0 0"/>
      </xacro:cylinder_inertial>
-->
    <visual>
      <geometry>
        <mesh filename="package://schunk_description/meshes/lwa4d/arm_1_link.stl"/>
      </geometry>
      <material name="Schunk/LightGrey"/>
    </visual>
    <collision>
      <geometry>
        <mesh filename="package://schunk_description/meshes/lwa4d/arm_1_link.stl"/>
      </geometry>
    </collision>
  </link>
  <!-- joint between arm_1_link and arm_2_link -->
  <joint name="robot_2_joint" type="revolute">
    <origin rpy="-1.570795 -1.570795 0" xyz="0 0 0.240"/>
    <parent link="robot_1_link"/>
    <child link="robot_2_link"/>
    <axis xyz="0 0 -1"/>
    <limit effort="216" lower="-2.12" upper="2.12" velocity="0.43633"/>
  </joint>
  <link name="robot_2_link">
    <inertial>
      <mass value="0.01"/>
      <origin xyz="0 0 0"/>
      <inertia ixx="0.001" ixy="0.0" ixz="0.0" iyy="0.001" iyz="0.0" izz="0.001"/>
    </inertial>
    <!--
      <xacro:cylinder_inertial radius="0.06" length="0.150" mass="2.0">
        <origin xyz="0 0 0" rpy="0 0 0"/>
      </xacro:cylinder_inertial>
-->
    <visual>
      <geometry>
        <mesh filename="package://schunk_description/meshes/lwa4d/arm_2_link.stl"/>
      </geometry>
      <material name="Schunk/Black"/>
    </visual>
    <collision>
      <geometry>
        <mesh filename="package://schunk_description/meshes/lwa4d/arm_2_link_collision.stl"/>
      </geometry>
    </collision>
  </link>
  <!-- joint between arm_2_link and arm_3_link -->
  <joint name="robot_3_joint" type="revolute">
    <origin rpy="1.570795 0 1.570795" xyz="0 0 0"/>
    <parent link="robot_2_link"/>
    <child link="robot_3_link"/>
    <axis xyz="0 0 -1"/>
    <limit effort="81.5" lower="-3.12159" upper="3.12159" velocity="0.4189"/>
  </joint>
  <link name="robot_3_link">
    <inertial>
      <mass value="0.01"/>
      <origin xyz="0 0 0"/>
      <inertia ixx="0.001" ixy="0.0" ixz="0.0" iyy="0.001" iyz="0.0" izz="0.001"/>
    </inertial>
    <!--
      <xacro:cylinder_inertial radius="0.06" length="0.2" mass="2.0">
        <origin xyz="0.0 0 -0.2" rpy="0 0 0"/>
      </xacro:cylinder_inertial>
-->
    <visual>
      <geometry>
        <mesh filename="package://schunk_description/meshes/lwa4d/arm_3_link.stl"/>
      </geometry>
      <material name="Schunk/LightGrey"/>
    </visual>
    <collision>
      <geometry>
        <mesh filename="package://schunk_description/meshes/lwa4d/arm_3_link_collision.stl"/>
      </geometry>
    </collision>
  </link>
  <!-- joint between arm_3_link and arm_4_link -->
  <joint name="robot_4_joint" type="revolute">
    <origin rpy="-1.570795 -1.570795 0" xyz="0 0 0.328"/>
    <parent link="robot_3_link"/>
    <child link="robot_4_link"/>
    <axis xyz="0 0 -1"/>
    <limit effort="81.5" lower="-2.16" upper="2.16" velocity="0.4189"/>
  </joint>
  <link name="robot_4_link">
    <inertial>
      <mass value="0.01"/>
      <origin xyz="0 0 0"/>
      <inertia ixx="0.001" ixy="0.0" ixz="0.0" iyy="0.001" iyz="0.0" izz="0.001"/>
    </inertial>
    <!--
      <xacro:cylinder_inertial radius="0.06" length="0.150" mass="1.2">
        <origin xyz="0 0 0" rpy="0 0 0"/>
      </xacro:cylinder_inertial>
-->
    <visual>
      <geometry>
        <mesh filename="package://schunk_description/meshes/lwa4d/arm_4_link.stl"/>
      </geometry>
      <material name="Schunk/Black"/>
    </visual>
    <collision>
      <geometry>
        <mesh filename="package://schunk_description/meshes/lwa4d/arm_4_link_collision.stl"/>
      </geometry>
    </collision>
  </link>
  <!-- joint between arm_4_link and arm_5_link -->
  <joint name="robot_5_joint" type="revolute">
    <origin rpy="1.570795 0 1.570795" xyz="0 0 0"/>
    <parent link="robot_4_link"/>
    <child link="robot_5_link"/>
    <axis xyz="0 0 -1"/>
    <limit effort="20.7" lower="-3.12159" upper="3.12159" velocity="0.43633"/>
  </joint>
  <link name="robot_5_link">
    <inertial>
      <mass value="0.01"/>
      <origin xyz="0 0 0"/>
      <inertia ixx="0.001" ixy="0.0" ixz="0.0" iyy="0.001" iyz="0.0" izz="0.001"/>
    </inertial>
    <!--
      <xacro:cylinder_inertial radius="0.06" length="0.15" mass="1.2">
        <origin xyz="0 0 -0.18" rpy="0 0 0"/>
      </xacro:cylinder_inertial>
-->
    <visual>
      <geometry>
        <mesh filename="package://schunk_description/meshes/lwa4d/arm_5_link.stl"/>
      </geometry>
      <material name="Schunk/LightGrey"/>
    </visual>
    <collision>
      <geometry>
        <mesh filename="package://schunk_description/meshes/lwa4d/arm_5_link_collision.stl"/>
      </geometry>
    </collision>
  </link>
  <!-- joint between arm_5_link and arm_6_link -->
  <joint name="robot_6_joint" type="revolute">
    <origin rpy="-1.570795 -1.570795 0" xyz="0 0 0.323"/>
    <parent link="robot_5_link"/>
    <child link="robot_6_link"/>
    <axis xyz="0 0 1"/>
    <limit effort="15" lower="-2.07" upper="2.07" velocity="1.2566"/>
  </joint>
  <link name="robot_6_link">
    <inertial>
      <mass value="0.01"/>
      <origin xyz="0 0 0"/>
      <inertia ixx="0.001" ixy="0.0" ixz="0.0" iyy="0.001" iyz="0.0" izz="0.001"/>
    </inertial>
    <!--
      <xacro:sphere_inertial radius="0.05" mass="1.9">
        <origin xyz="0 0 0" rpy="0 0 0"/>
      </xacro:sphere_inertial>
-->
    <visual>
      <geometry>
        <mesh filename="package://schunk_description/meshes/lwa4d/arm_6_link.stl"/>
      </geometry>
      <material name="Schunk/Black"/>
    </visual>
    <collision>
      <geometry>
        <mesh filename="package://schunk_description/meshes/lwa4d/arm_6_link_collision.stl"/>
      </geometry>
    </collision>
  </link>
  <!-- joint between arm_6_link and arm_7_link -->
  <joint name="robot_7_joint" type="revolute">
    <origin rpy="1.570795 0 1.570795" xyz="0 0 0"/>
    <parent link="robot_6_link"/>
    <child link="robot_7_link"/>
    <axis xyz="0 0 1"/>
    <limit effort="15" lower="-2.94" upper="2.94" velocity="1.2566"/>
  </joint>
  <link name="robot_7_link">
    <inertial>
      <mass value="0.01"/>
      <origin xyz="0 0 0"/>
      <inertia ixx="0.001" ixy="0.0" ixz="0.0" iyy="0.001" iyz="0.0" izz="0.001"/>
    </inertial>
    <!--
      <xacro:cylinder_inertial radius="0.03" length="0.035" mass="0.05">
        <origin xyz="0 0 0.06" rpy="0 0 0"/>
      </xacro:cylinder_inertial>
-->
    <visual>
      <geometry>
        <mesh filename="package://schunk_description/meshes/lwa4d/arm_7_link.stl"/>
      </geometry>
      <material name="Schunk/LightGrey"/>
    </visual>
    <collision>
      <geometry>
        <mesh filename="package://schunk_description/meshes/lwa4d/arm_7_link.stl"/>
      </geometry>
    </collision>
  </link>
  <joint name="robot_ee_joint" type="fixed">
    <origin rpy="0 0 0" xyz="0 0 0.0824"/>
    <parent link="robot_7_link"/>
    <child link="robot_ee_link"/>
  </joint>
  <link name="robot_ee_link">
    <inertial>
      <mass value="0.01"/>
      <origin xyz="0 0 0"/>
      <inertia ixx="0.001" ixy="0.0" ixz="0.0" iyy="0.001" iyz="0.0" izz="0.001"/>
    </inertial>
  </link>
  <gazebo reference="robot_base_link">
    <gravity>true</gravity>
    <self_collide>false</self_collide>
    <material value="Schunk/Black"/>
  </gazebo>
  <gazebo reference="robot_1_link">
    <gravity>true</gravity>
    <self_collide>false</self_collide>
    <material value="Schunk/LightGrey"/>
  </gazebo>
  <gazebo reference="robot_2_link">
    <gravity>true</gravity>
    <self_collide>false</self_collide>
    <material value="Schunk/Black"/>
  </gazebo>
  <gazebo reference="robot_3_link">
    <gravity>true</gravity>
    <self_collide>false</self_collide>
    <material value="Schunk/LightGrey"/>
  </gazebo>
  <gazebo reference="robot_4_link">
    <gravity>true</gravity>
    <self_collide>false</self_collide>
    <material value="Schunk/Black"/>
  </gazebo>
  <gazebo reference="robot_5_link">
    <gravity>true</gravity>
    <self_collide>false</self_collide>
    <material value="Schunk/LightGrey"/>
  </gazebo>
  <gazebo reference="robot_6_link">
    <gravity>true</gravity>
    <self_collide>false</self_collide>
    <material value="Schunk/Black"/>
  </gazebo>
  <gazebo reference="robot_7_link">
    <gravity>true</gravity>
    <self_collide>false</self_collide>
    <material value="Schunk/LightGrey"/>
  </gazebo>
  <transmission name="robot_1_trans">
    <type>transmission_interface/SimpleTransmission</type>
    <joint name="robot_1_joint">
      <hardwareInterface>PositionJointInterface</hardwareInterface>
      <hardwareInterface>VelocityJointInterface</hardwareInterface>
      <!--hardwareInterface>EffortJointInterface</hardwareInterface-->
    </joint>
    <actuator name="robot_1_motor">
      <mechanicalReduction>1</mechanicalReduction>
    </actuator>
  </transmission>
  <transmission name="robot_2_trans">
    <type>transmission_interface/SimpleTransmission</type>
    <joint name="robot_2_joint">
      <hardwareInterface>PositionJointInterface</hardwareInterface>
      <hardwareInterface>VelocityJointInterface</hardwareInterface>
      <!--hardwareInterface>EffortJointInterface</hardwareInterface-->
    </joint>
    <actuator name="robot_2_motor">
      <mechanicalReduction>1</mechanicalReduction>
    </actuator>
  </transmission>
  <transmission name="robot_3_trans">
    <type>transmission_interface/SimpleTransmission</type>
    <joint name="robot_3_joint">
      <hardwareInterface>PositionJointInterface</hardwareInterface>
      <hardwareInterface>VelocityJointInterface</hardwareInterface>
      <!--hardwareInterface>EffortJointInterface</hardwareInterface-->
    </joint>
    <actuator name="robot_3_motor">
      <mechanicalReduction>1</mechanicalReduction>
    </actuator>
  </transmission>
  <transmission name="robot_4_trans">
    <type>transmission_interface/SimpleTransmission</type>
    <joint name="robot_4_joint">
      <hardwareInterface>PositionJointInterface</hardwareInterface>
      <hardwareInterface>VelocityJointInterface</hardwareInterface>
      <!--hardwareInterface>EffortJointInterface</hardwareInterface-->
    </joint>
    <actuator name="robot_4_motor">
      <mechanicalReduction>1</mechanicalReduction>
    </actuator>
  </transmission>
  <transmission name="robot_5_trans">
    <type>transmission_interface/SimpleTransmission</type>
    <joint name="robot_5_joint">
      <hardwareInterface>PositionJointInterface</hardwareInterface>
      <hardwareInterface>VelocityJointInterface</hardwareInterface>
      <!--hardwareInterface>EffortJointInterface</hardwareInterface-->
    </joint>
    <actuator name="robot_5_motor">
      <mechanicalReduction>1</mechanicalReduction>
    </actuator>
  </transmission>
  <transmission name="robot_6_trans">
    <type>transmission_interface/SimpleTransmission</type>
    <joint name="robot_6_joint">
      <hardwareInterface>PositionJointInterface</hardwareInterface>
      <hardwareInterface>VelocityJointInterface</hardwareInterface>
      <!--hardwareInterface>EffortJointInterface</hardwareInterface-->
    </joint>
    <actuator name="robot_6_motor">
      <mechanicalReduction>1</mechanicalReduction>
    </actuator>
  </transmission>
  <transmission name="robot_7_trans">
    <type>transmission_interface/SimpleTransmission</type>
    <joint name="robot_7_joint">
      <hardwareInterface>PositionJointInterface</hardwareInterface>
      <hardwareInterface>VelocityJointInterface</hardwareInterface>
      <!--hardwareInterface>EffortJointInterface</hardwareInterface-->
    </joint>
    <actuator name="robot_7_motor">
      <mechanicalReduction>1</mechanicalReduction>
    </actuator>
  </transmission>
  <!-- ros_control plugin -->
  <gazebo>
    <plugin filename="libhwi_switch_gazebo_ros_control.so" name="ros_control">
      <robotNamespace>robot</robotNamespace>
      <filterJointsParam>joint_names</filterJointsParam>
    </plugin>
  </gazebo>
</robot>
